Workbook

Sheet Content
B1: TCS — Consolidated Statement of Profit & Loss
B3: Assumptions | C3: Assumptions
B5: Working
B7: Asset Schedule | C7: Asset schedule'
B8: Equity Schedule | C8: Equity Schedule'
B10: Output
B12: P/L | C12: P&L
B13: Balance Sheet | C13: Balance Sheet
B14: Cash Flow | C14: Cash Flow
B16: Valuation | C16: Valuation

Sheet Assumptions
A1: TCS — TATA CONSULTANCY SERVICES
B2: Revenue Assumptions
B3: Year | C3: 45016 | D3: 45382 | E3: 45747 | F3: 46112 | G3: 46477 | H3: 46843 | I3: 47208 | J3: 47573 | K3: 47938
B4: Key Drivers
B5: Headcounts (No. of employees) | C5: 614795 | D5: 601546 | E5: 607979 | F5: 584519 | G5: =F5*(1+G6) -> 590364.19 | H5: =G5*(1+H6) -> 599219.65 | I5: =H5*(1+I6) -> 611204.05 | J5: =I5*(1+J6) -> 623428.13 | K5: =J5*(1+K6) -> 635896.69
B6: Growth | D6: =D5/C5-1 -> -0.021550273 | E6: =E5/D5-1 -> 0.010694112 | F6: =F5/E5-1 -> -0.038586859 | G6: 0.01 | H6: =MIN(G6+0.5%,2%) -> 0.015 | I6: =MIN(H6+0.5%,2%) -> 0.02 | J6: =MIN(I6+0.5%,2%) -> 0.02 | K6: =MIN(J6+0.5%,2%) -> 0.02
B7: Revenue per employee | C7: ='P&L'!C7/Assumptions!C5 -> 0.36672061 | D7: ='P&L'!D4/Assumptions!D5 -> 0.40045649 | E7: ='P&L'!E4/Assumptions!E5 -> 0.41995529 | F7: ='P&L'!F4/Assumptions!F5 -> 0.45682176 | G7: =F7*(1+G8) -> 0.49161201 | H7: =G7*(1+H8) -> 0.52905179 | I7: =H7*(1+I8) -> 0.56934287 | J7: =I7*(1+J8) -> 0.61270241 | K7: =J7*(1+K8) -> 0.65936409
B8: Growth | D8: =D7/C7-1 -> 0.0919934 | E8: =E7/D7-1 -> 0.048691442 | F8: =F7/E7-1 -> 0.08778665 | G8: =AVERAGE(D8:F8) -> 0.076157164 | H8: =G8 -> 0.076157164 | I8: =H8 -> 0.076157164 | J8: =I8 -> 0.076157164 | K8: =J8 -> 0.076157164
B9: Total revenue | C9: ='P&L'!C7 -> 225458 | D9: =D5*D7 -> 240893 | E9: =E5*E7 -> 255324 | F9: =F5*F7 -> 267021 | G9: =G5*G7 -> 290230.13 | H9: =H5*H7 -> 317018.23 | I9: =I5*I7 -> 347984.67 | J9: =J5*J7 -> 381975.92 | K9: =K5*K7 -> 419287.44
B10: Other income | C10: 3449 | D10: 4422 | E10: 3962 | F10: 4402 | G10: =G9*G11 -> 4871.9801 | H10: =H9*H11 -> 5321.6615 | I10: =I9*I11 -> 5841.483 | J10: =J9*J11 -> 6412.0809 | K10: =K9*K11 -> 7038.4149
B11: % of revenue | C11: =C10/C9 -> 0.015297749 | D11: =D10/D9 -> 0.018356698 | E11: =E10/E9 -> 0.015517539 | F11: =F10/F9 -> 0.016485595 | G11: =AVERAGE(D11:F11) -> 0.01678661 | H11: =G11 -> 0.01678661 | I11: =H11 -> 0.01678661 | J11: =I11 -> 0.01678661 | K11: =J11 -> 0.01678661
B12: Expenses Assumptions
B14: Employee Benefit Expenses | C14: 127522 | D14: 140131 | E14: 145788 | F14: 154994 | G14: =G9*G15 -> 166793.53 | H14: =H9*H15 -> 182188.49 | I14: =I9*I15 -> 199984.72 | J14: =J9*J15 -> 219519.28 | K14: =K9*K15 -> 240962
B15: % of revenue | C15: =C14/C9 -> 0.56561311 | D15: =D14/D9 -> 0.5817147 | E15: =E14/E9 -> 0.57099215 | F15: =F14/F9 -> 0.58045622 | G15: =AVERAGE(C15:F15) -> 0.57469405 | H15: =G15 -> 0.57469405 | I15: =H15 -> 0.57469405 | J15: =I15 -> 0.57469405 | K15: =J15 -> 0.57469405
B16: Cost of Equipment & Software | C16: 1881 | D16: 3702 | E16: 11648 | F16: 4399 | G16: =G9*G17 -> 7493.9978 | H16: =H9*H17 -> 8185.6902 | I16: =I9*I17 -> 8985.2709 | J16: =J9*J17 -> 9862.955 | K16: =K9*K17 -> 10826.371
B17: % of revenue | C17: =C16/C9 -> 0.0083430173 | D17: =D16/D9 -> 0.015367819 | E17: =E16/E9 -> 0.045620467 | F17: =F16/F9 -> 0.01647436 | G17: =AVERAGE(D17:F17) -> 0.025820882 | H17: =G17 -> 0.025820882 | I17: =H17 -> 0.025820882 | J17: =I17 -> 0.025820882 | K17: =J17 -> 0.025820882
B18: Other Expenses | C18: 36796 | D18: 32764 | E18: 30481 | F18: 35230 | G18: =G9*G19 -> 36020.406 | H18: =H9*H19 -> 37759.981 | I18: =I9*I19 -> 39708.464 | J18: =J9*J19 -> 41677.32 | K18: =K9*K19 -> 43651.936
B19: % of revenue | C19: =C18/C9 -> 0.16320556 | D19: =D18/D9 -> 0.13601059 | E19: =E18/E9 -> 0.11938165 | F19: =F18/F9 -> 0.13193719 | G19: =AVERAGE(D19:F19)-0.5% -> 0.12410981 | H19: =G19-0.5% -> 0.11910981 | I19: =H19-0.5% -> 0.11410981 | J19: =I19-0.5% -> 0.10910981 | K19: =J19-0.5% -> 0.10410981
B21: Finance Cost Implied Rate | C21: 0.1
B24: Opening Lease liability
B25: Depreciation and Amortization
B26: Depreciation on PPE | C26: 2892 | D26: 2790 | E26: 2695 | F26: 2641 | G26: ='Asset schedule'!G15 -> 2664.601 | H26: ='Asset schedule'!H15 -> 2584.4384 | I26: ='Asset schedule'!I15 -> 2495.9418 | J26: ='Asset schedule'!J15 -> 2397.7484 | K26: ='Asset schedule'!K15 -> 2288.0956
B27: Depreciation on ROU | C27: 1634 | D27: 1716 | E27: 1820 | F27: 1866 | G27: =F27 -> 1866 | H27: =G27 -> 1866 | I27: =H27 -> 1866 | J27: =I27 -> 1866 | K27: =J27 -> 1866
B28: Amortization | C28: 496 | D28: 479 | E28: 727 | F28: 1053 | G28: ='Asset schedule'!G39 -> 110 | H28: ='Asset schedule'!H39 -> 87 | I28: ='Asset schedule'!I39 -> 67 | J28: ='Asset schedule'!J39 -> 45 | K28: ='Asset schedule'!K39 -> 40
C29: =SUM(C26:C28) -> 5022 | D29: =SUM(D26:D28) -> 4985 | E29: =SUM(E26:E28) -> 5242 | F29: =SUM(F26:F28) -> 5560 | G29: =SUM(G26:G28) -> 4640.601 | H29: =SUM(H26:H28) -> 4537.4384 | I29: =SUM(I26:I28) -> 4428.9418 | J29: =SUM(J26:J28) -> 4308.7484 | K29: =SUM(K26:K28) -> 4194.0956
B31: TAX
B32: Effective Tax rate | C32: ='P&L'!C30/'P&L'!C26 -> 0.25662924 | D32: ='P&L'!D30/'P&L'!D26 -> 0.25643176 | E32: ='P&L'!E30/'P&L'!E26 -> 0.25308047 | F32: ='P&L'!F30/'P&L'!F26 -> 0.24482722 | G32: =AVERAGE(C32:F32) -> 0.25274217 | H32: =G32 -> 0.25274217 | I32: =H32 -> 0.25274217 | J32: =I32 -> 0.25274217 | K32: =J32 -> 0.25274217
B33: Balance sheet Assumptions
B34: Current year Dep. For PPE | C34: 2892 | D34: 2790 | E34: 2695 | F34: 2641
B35: Average Gross Block PPE | D35: =('Asset schedule'!C9+'Asset schedule'!D9)/2 -> 33098.5 | E35: =('Asset schedule'!D9+'Asset schedule'!E9)/2 -> 35565 | F35: =('Asset schedule'!E9+'Asset schedule'!F9)/2 -> 38242.5
B36: % of Depreciation | D36: =D34/D35 -> 0.08429385 | E36: =E34/E35 -> 0.075776747 | F36: =F34/F35 -> 0.069059293 | G36: =AVERAGE(D36:F36)-1% -> 0.06637663 | H36: =(G36)-0.5% -> 0.06137663 | I36: =(H36)-0.5% -> 0.05637663 | J36: =(I36)-0.5% -> 0.05137663 | K36: =(J36)-0.5% -> 0.04637663
B38: Disposal | C38: 458 | D38: 502 | E38: 869 | F38: 1459
B39: % of Opening Gross block | C39: =C38/'Asset schedule'!C5 -> 0.015115512 | D39: =D38/'Asset schedule'!D5 -> 0.015520653 | E39: =E38/'Asset schedule'!E5 -> 0.025669808 | F39: =F38/'Asset schedule'!F5 -> 0.039139416 | G39: =AVERAGE(C39:F39) -> 0.023861347 | H39: =G39 -> 0.023861347 | I39: =H39 -> 0.023861347 | J39: =I39 -> 0.023861347 | K39: =J39 -> 0.023861347
B40: Organic CAPEX | C40: 2314 | D40: 1923 | E40: 2706 | F40: 2606 | G40: =F40*(1+G41) -> 2806.8791 | H40: =G40*(1+H41) -> 3037.277 | I40: =H40*(1+I41) -> 3301.7731 | J40: =I40*(1+J41) -> 3605.8112 | K40: =J40*(1+K41) -> 3955.8753
D41: =D40/C40-1 -> -0.16897148 | E41: =E40/D40-1 -> 0.40717629 | F41: =F40/E40-1 -> -0.036954915 | G41: =AVERAGE(D41:F41)+1% -> 0.077083298 | H41: =G41+0.5% -> 0.082083298 | I41: =H41+0.5% -> 0.087083298 | J41: =I41+0.5% -> 0.092083298 | K41: =J41+0.5% -> 0.097083298
B43: CWIP | C43: 1234 | D43: 1564 | E43: 1546 | F43: 2665 | G43: ='Asset schedule'!G5*Assumptions!G44 -> 2163.171 | H43: ='Asset schedule'!H5*Assumptions!H44 -> 2266.415 | I43: ='Asset schedule'!I5*Assumptions!I44 -> 2379.907 | J43: ='Asset schedule'!J5*Assumptions!J44 -> 2505.2835 | K43: ='Asset schedule'!K5*Assumptions!K44 -> 2644.4427
B44: % of Gross PPE | C44: =C43/'Asset schedule'!C5 -> 0.040726073 | D44: =D43/'Asset schedule'!D5 -> 0.048355182 | E44: =E43/'Asset schedule'!E5 -> 0.045668035 | F44: =F43/'Asset schedule'!F5 -> 0.071491805 | G44: =AVERAGE(D44:F44) -> 0.055171674 | H44: =G44 -> 0.055171674 | I44: =H44 -> 0.055171674 | J44: =I44 -> 0.055171674 | K44: =J44 -> 0.055171674
B49: Current Asset
B50: Inventories | C50: 28 | D50: 28 | E50: 21 | F50: 29 | G50: =F50 -> 29 | H50: =G50 -> 29 | I50: =H50 -> 29 | J50: =I50 -> 29 | K50: =J50 -> 29 | L50: Constant
B51: Investments (current) | C51: 36897 | D51: 31481 | E51: 30689 | F51: 33770 | G51: ='P&L'!G4*Assumptions!G52 -> 36506.145 | H51: ='P&L'!H4*Assumptions!H52 -> 39875.645 | I51: ='P&L'!I4*Assumptions!I52 -> 43770.71 | J51: ='P&L'!J4*Assumptions!J52 -> 48046.246 | K51: ='P&L'!K4*Assumptions!K52 -> 52739.418
...

Sheet P&L
B1: TCS — Consolidated Statement of Profit & Loss
B2: ₹ Crore | Source: Annual Reports FY25, FY26
B3: Year | C3: 45016 | D3: 45382 | E3: 45747 | F3: 46112 | G3: 46477 | H3: 46843 | I3: 47208 | J3: 47573 | K3: 47938
B4: Revenue from Operations | C4: 225458 | D4: 240893 | E4: 255324 | F4: 267021 | G4: =Assumptions!G9 -> 290230.13 | H4: =Assumptions!H9 -> 317018.23 | I4: =Assumptions!I9 -> 347984.67 | J4: =Assumptions!J9 -> 381975.92 | K4: =Assumptions!K9 -> 419287.44
B5: Revenue Growth | D5: =D4/C4-1 -> 0.068460645 | E5: =E4/D4-1 -> 0.059906265 | F5: =F4/E4-1 -> 0.04581238 | G5: =G4/F4-1 -> 0.086918736 | H5: =H4/G4-1 -> 0.092299522 | I5: =I4/H4-1 -> 0.097680307 | J5: =J4/I4-1 -> 0.097680307 | K5: =K4/J4-1 -> 0.097680307
B7: Revenue | C7: =C4 -> 225458 | D7: =D4 -> 240893 | E7: =E4 -> 255324 | F7: =F4 -> 267021 | G7: =G4 -> 290230.13 | H7: =H4 -> 317018.23 | I7: =I4 -> 347984.67 | J7: =J4 -> 381975.92 | K7: =K4 -> 419287.44
B9: Employee Benefit Expenses | C9: 127522 | D9: 140131 | E9: 145788 | F9: 154994 | G9: =Assumptions!G14 -> 166793.53 | H9: =Assumptions!H14 -> 182188.49 | I9: =Assumptions!I14 -> 199984.72 | J9: =Assumptions!J14 -> 219519.28 | K9: =Assumptions!K14 -> 240962
B10: Cost of Equipment & Software | C10: 1881 | D10: 3702 | E10: 11648 | F10: 4399 | G10: =Assumptions!G16 -> 7493.9978 | H10: =Assumptions!H16 -> 8185.6902 | I10: =Assumptions!I16 -> 8985.2709 | J10: =Assumptions!J16 -> 9862.955 | K10: =Assumptions!K16 -> 10826.371
B11: Other Expenses | C11: 36796 | D11: 32764 | E11: 30481 | F11: 35230 | G11: =Assumptions!G18 -> 36020.406 | H11: =Assumptions!H18 -> 37759.981 | I11: =Assumptions!I18 -> 39708.464 | J11: =Assumptions!J18 -> 41677.32 | K11: =Assumptions!K18 -> 43651.936
B12: Total expenses | C12: =SUM(C9:C11) -> 166199 | D12: =SUM(D9:D11) -> 176597 | E12: =SUM(E9:E11) -> 187917 | F12: =SUM(F9:F11) -> 194623 | G12: =SUM(G9:G11) -> 210307.93 | H12: =SUM(H9:H11) -> 228134.16 | I12: =SUM(I9:I11) -> 248678.45 | J12: =SUM(J9:J11) -> 271059.56 | K12: =SUM(K9:K11) -> 295440.3
B14: EBITDA | C14: =C7-C12 -> 59259 | D14: =D7-D12 -> 64296 | E14: =E7-E12 -> 67407 | F14: =F7-F12 -> 72398 | G14: =G7-G12 -> 79922.198 | H14: =H7-H12 -> 88884.069 | I14: =I7-I12 -> 99306.216 | J14: =J7-J12 -> 110916.36 | K14: =K7-K12 -> 123847.14
B15: EBITDA Margin | D15: =D14/D7 -> 0.26690688 | E15: =E14/E7 -> 0.26400573 | F15: =F14/F7 -> 0.27113223 | G15: =G14/G7 -> 0.27537526 | H15: =H14/H7 -> 0.28037526 | I15: =I14/I7 -> 0.28537526 | J15: =J14/J7 -> 0.29037526 | K15: =K14/K7 -> 0.29537526
B17: Depreciation & Amortisation | C17: 5022 | D17: 4985 | E17: 5242 | F17: 5560 | G17: =Assumptions!G29 -> 4640.601 | H17: =Assumptions!H29 -> 4537.4384 | I17: =Assumptions!I29 -> 4428.9418 | J17: =Assumptions!J29 -> 4308.7484 | K17: =Assumptions!K29 -> 4194.0956
B18: EBIT | C18: =C14-C17 -> 54237 | D18: =D14-D17 -> 59311 | E18: =E14-E17 -> 62165 | F18: =F14-F17 -> 66838 | G18: =G14-G17 -> 75281.597 | H18: =H14-H17 -> 84346.631 | I18: =I14-I17 -> 94877.274 | J18: =J14-J17 -> 106607.61 | K18: =K14-K17 -> 119653.04
B19: EBIT Margin | D19: =D18/D7 -> 0.24621305 | E19: =E18/E7 -> 0.24347496 | F19: =F18/F7 -> 0.2503099 | G19: =G18/G7 -> 0.25938588 | H19: =H18/H7 -> 0.2660624 | I19: =I18/I7 -> 0.27264786 | J19: =J18/J7 -> 0.27909511 | K19: =K18/K7 -> 0.28537235
B21: Other income | C21: 3449 | D21: 4422 | E21: 3962 | F21: 4402 | G21: =Assumptions!G10 -> 4871.9801 | H21: =Assumptions!H10 -> 5321.6615 | I21: =Assumptions!I10 -> 5841.483 | J21: =Assumptions!J10 -> 6412.0809 | K21: =Assumptions!K10 -> 7038.4149
B22: Finance Costs | C22: -779 | D22: -778 | E22: -796 | F22: -1227 | G22: =F22 -> -1227 | H22: =G22 -> -1227 | I22: =H22 -> -1227 | J22: =I22 -> -1227 | K22: =J22 -> -1227
B24: Profit Before Execptional & Tax | C24: =SUM(C18,C21,C22) -> 56907 | D24: =SUM(D18,D21,D22) -> 62955 | E24: =SUM(E18,E21,E22) -> 65331 | F24: =SUM(F18,F21,F22) -> 70013 | G24: =SUM(G18,G21,G22) -> 78926.577 | H24: =SUM(H18,H21,H22) -> 88441.293 | I24: =SUM(I18,I21,I22) -> 99491.757 | J24: =SUM(J18,J21,J22) -> 111792.69 | K24: =SUM(K18,K21,K22) -> 125464.46
B25: Exceptional Items | D25: 958 | E25: 0 | F25: 4526
B26: Profit Before Tax(PBT) | C26: =C24-C25 -> 56907 | D26: =D24-D25 -> 61997 | E26: =E24-E25 -> 65331 | F26: =F24-F25 -> 65487 | G26: =G24-G25 -> 78926.577 | H26: =H24-H25 -> 88441.293 | I26: =I24-I25 -> 99491.757 | J26: =J24-J25 -> 111792.69 | K26: =K24-K25 -> 125464.46
B28: Current Tax | C28: 14757 | D28: 15864 | E28: 16910 | F28: 16388
B29: Deferred Tax | C29: -153 | D29: 34 | E29: -376 | F29: -355
B30: Total tax expense | C30: =SUM(C28:C29) -> 14604 | D30: =D28+D29 -> 15898 | E30: =E28+E29 -> 16534 | F30: =F28+F29 -> 16033 | G30: =G26*Assumptions!G32 -> 19948.074 | H30: =H26*Assumptions!H32 -> 22352.844 | I30: =I26*Assumptions!I32 -> 25145.763 | J30: =J26*Assumptions!J32 -> 28254.727 | K30: =K26*Assumptions!K32 -> 31710.159
B32: Profit after Tax (PAT) | C32: =C26-C30 -> 42303 | D32: =D26-D30 -> 46099 | E32: =E26-E30 -> 48797 | F32: =F26-F30 -> 49454 | G32: =G26-G30 -> 58978.502 | H32: =H26-H30 -> 66088.448 | I32: =I26-I30 -> 74345.994 | J32: =J26-J30 -> 83537.963 | K32: =K26-K30 -> 93754.298
B33: PAT Margin | D33: =D32/D7 -> 0.19136712 | E33: =E32/E7 -> 0.19111795 | F33: =F32/F7 -> 0.18520641 | G33: =G32/G7 -> 0.20321289 | H33: =H32/H7 -> 0.20846892 | I33: =I32/I7 -> 0.21364733 | J33: =J32/J7 -> 0.21869955 | K33: =K32/K7 -> 0.22360388
B35: Attributable to Shareholders | D35: 45908 | E35: 48553 | F35: 49210
B36: Attributable to NCI | D36: 191 | E36: 244 | F36: 244

Sheet Balance Sheet
B1: TCS — Consolidated Balance Sheet
B2: ₹ Crore | Source: Annual Reports FY25, FY26
B3: Year | D3: 45382 | E3: 45747 | F3: 46112 | G3: 46477 | H3: 46843 | I3: 47208 | J3: 47573 | K3: 47938
B4: Asset
B5: Non - Current Asset
B6: Property, Plant & Equipment (net) | C6: 10230 | D6: 9376 | E6: 10978 | F6: 11032 | G6: ='Asset schedule'!G11 -> 10238.722 | H6: ='Asset schedule'!H11 -> 9711.353 | I6: ='Asset schedule'!I11 -> 9487.8918 | J6: ='Asset schedule'!J11 -> 9612.4378 | K6: ='Asset schedule'!K11 -> 10136.515
B7: Capital Work-in-Progress | C7: 1234 | D7: 1564 | E7: 1546 | F7: 2665 | G7: =Assumptions!G43 -> 2163.171 | H7: =Assumptions!H43 -> 2266.415 | I7: =Assumptions!I43 -> 2379.907 | J7: =Assumptions!J43 -> 2505.2835 | K7: =Assumptions!K43 -> 2644.4427
B8: Right-of-Use Assets | C8: 7560 | D8: 7886 | E8: 9275 | F8: 11027 | G8: ='Asset schedule'!G24 -> 11027 | H8: ='Asset schedule'!H24 -> 11027 | I8: ='Asset schedule'!I24 -> 11027 | J8: ='Asset schedule'!J24 -> 11027 | K8: ='Asset schedule'!K24 -> 11027
B9: Goodwill | C9: 1858 | D9: 1832 | E9: 1860 | F9: 9108 | G9: =F9 -> 9108 | H9: =G9 -> 9108 | I9: =H9 -> 9108 | J9: =I9 -> 9108 | K9: =J9 -> 9108
B10: Other Intangible Assets | C10: 867 | D10: 510 | E10: 940 | F10: 176 | G10: ='Asset schedule'!G43 -> 266 | H10: ='Asset schedule'!H43 -> 379 | I10: ='Asset schedule'!I43 -> 512 | J10: ='Asset schedule'!J43 -> 667 | K10: ='Asset schedule'!K43 -> 827
B11: Other Non-current Assets | C11: 11632 | D11: 12297 | E11: 12019 | F11: 12659 | G11: =F11 -> 12659 | H11: =G11 -> 12659 | I11: =H11 -> 12659 | J11: =I11 -> 12659 | K11: =J11 -> 12659 | O11: 11632
B14: Total Non-Current Assets | C14: =SUM(C6:C11) -> 33381 | D14: =SUM(D6:D11) -> 33465 | E14: =SUM(E6:E11) -> 36618 | F14: =SUM(F6:F11) -> 46667 | G14: =SUM(G6:G11) -> 45461.893 | H14: =SUM(H6:H11) -> 45150.768 | I14: =SUM(I6:I11) -> 45173.799 | J14: =SUM(J6:J11) -> 45578.721 | K14: =SUM(K6:K11) -> 46401.958
B16: Current Asset
B17: Inventories | C17: 28 | D17: 28 | E17: 21 | F17: 29 | G17: =F17 -> 29 | H17: =G17 -> 29 | I17: =H17 -> 29 | J17: =I17 -> 29 | K17: =J17 -> 29
B18: Investments (current) | C18: 36897 | D18: 31481 | E18: 30689 | F18: 33770 | G18: =Assumptions!G51 -> 36506.145 | H18: =Assumptions!H51 -> 39875.645 | I18: =Assumptions!I51 -> 43770.71 | J18: =Assumptions!J51 -> 48046.246 | K18: =Assumptions!K51 -> 52739.418
B19: Trade Receivables | C19: 49954 | D19: 53577 | E19: 59046 | F19: 67714 | G19: =('P&L'!G4/365)*Assumptions!G53 -> 68422.681 | H19: =('P&L'!H4/365)*Assumptions!H53 -> 74738.062 | I19: =('P&L'!I4/365)*Assumptions!I53 -> 82038.499 | J19: =('P&L'!J4/365)*Assumptions!J53 -> 90052.044 | K19: =('P&L'!K4/365)*Assumptions!K53 -> 98848.356
B20: Cash & Cash Equivalents | C20: 7123 | D20: 9016 | E20: 8342 | F20: 6417 | G20: ='Cash Flow'!G41 -> 15549.843 | H20: ='Cash Flow'!H41 -> 16758.085 | I20: ='Cash Flow'!I41 -> 17536.493 | J20: ='Cash Flow'!J41 -> 14936.06 | K20: ='Cash Flow'!K41 -> 11901.704 | L20: From cashflow
B21: Other Balances with Banks | C21: 3909 | D21: 4270 | E21: 7121 | F21: 6491 | G21: =Assumptions!G55 -> 6764.753 | H21: =Assumptions!H55 -> 7389.1365 | I21: =Assumptions!I55 -> 8110.9096 | J21: =Assumptions!J55 -> 8903.1857 | K21: =Assumptions!K55 -> 9772.8517
B22: Other Current Assets | C22: 12359 | D22: 14612 | E22: 17792 | F22: 21284 | G22: =F22 -> 21284 | H22: =G22 -> 21284 | I22: =H22 -> 21284 | J22: =I22 -> 21284 | K22: =J22 -> 21284
B23: Total Current Assets | C23: =SUM(C17:C22) -> 110270 | D23: =SUM(D17:D22) -> 112984 | E23: =SUM(E17:E22) -> 123011 | F23: =SUM(F17:F22) -> 135705 | G23: =SUM(G17:G22) -> 148556.42 | H23: =SUM(H17:H22) -> 160073.93 | I23: =SUM(I17:I22) -> 172769.61 | J23: =SUM(J17:J22) -> 183250.54 | K23: =SUM(K17:K22) -> 194575.33
B25: Total Assets | C25: =SUM(C14,C23) -> 143651 | D25: =SUM(D14,D23) -> 146449 | E25: =SUM(E14,E23) -> 159629 | F25: =SUM(F14,F23) -> 182372 | G25: =SUM(G14,G23) -> 194018.32 | H25: =SUM(H14,H23) -> 205224.7 | I25: =SUM(I14,I23) -> 217943.41 | J25: =SUM(J14,J23) -> 228829.26 | K25: =SUM(K14,K23) -> 240977.29
B27: Equity & Liabilities
B28: Equity
B29: Share Capital | D29: 362 | E29: 362 | F29: 362 | G29: =F29 -> 362 | H29: =G29 -> 362 | I29: =H29 -> 362 | J29: =I29 -> 362 | K29: =J29 -> 362
B30: Other Equity (Reserves & Surplus) | D30: 90127 | E30: 94394 | F30: 106878 | G30: ='Equity Schedule'!G8 -> 117494.13 | H30: ='Equity Schedule'!H8 -> 125424.74 | I30: ='Equity Schedule'!I8 -> 134346.26 | J30: ='Equity Schedule'!J8 -> 141029.3 | K30: ='Equity Schedule'!K8 -> 148529.64
B32: Non-Controlling Interests | D32: 830 | E32: 1015 | F32: 1238 | G32: =F32 -> 1238 | H32: =G32 -> 1238 | I32: =H32 -> 1238 | J32: =I32 -> 1238 | K32: =J32 -> 1238
B33: Total Equity | D33: =SUM(D29:D32) -> 91319 | E33: =SUM(E29:E32) -> 95771 | F33: =SUM(F29:F32) -> 108478 | G33: =SUM(G29:G32) -> 119094.13 | H33: =SUM(H29:H32) -> 127024.74 | I33: =SUM(I29:I32) -> 135946.26 | J33: =SUM(J29:J32) -> 142629.3 | K33: =SUM(K29:K32) -> 150129.64
B35: Non-Current Liabilities
B36: Lease Liabilities (non-current) | D36: 6516 | E36: 7838 | F36: 9453 | G36: =F36 -> 9453 | H36: =G36 -> 9453 | I36: =H36 -> 9453 | J36: =I36 -> 9453 | K36: =J36 -> 9453
B37: Other Non-current Liabilities | D37: 2510 | E37: 3019 | F37: 3527 | G37: =F37 -> 3527 | H37: =G37 -> 3527 | I37: =H37 -> 3527 | J37: =I37 -> 3527 | K37: =J37 -> 3527
B38: Total Non-Current Liabilities | D38: =SUM(D36:D37) -> 9026 | E38: =SUM(E36:E37) -> 10857 | F38: =SUM(F36:F37) -> 12980 | G38: =SUM(G36:G37) -> 12980 | H38: =SUM(H36:H37) -> 12980 | I38: =SUM(I36:I37) -> 12980 | J38: =SUM(J36:J37) -> 12980 | K38: =SUM(K36:K37) -> 12980
B40: Current Liabilities
B41: Lease Liabilities (current) | D41: 1505 | E41: 1554 | F41: 1830 | G41: =F41 -> 1830 | H41: =G41 -> 1830 | I41: =H41 -> 1830 | J41: =I41 -> 1830 | K41: =J41 -> 1830
B42: Trade Payables | D42: 9981 | E42: 13909 | F42: 14808 | G42: =('P&L'!G9/365)*Assumptions!G62 -> 14576.145 | H42: =('P&L'!H9/365)*Assumptions!H62 -> 15921.516 | I42: =('P&L'!I9/365)*Assumptions!I62 -> 17476.734 | J42: =('P&L'!J9/365)*Assumptions!J62 -> 19183.867 | K42: =('P&L'!K9/365)*Assumptions!K62 -> 21057.753
B43: Other Financial Liabilities | D43: 8362 | E43: 8542 | F43: 11194 | G43: =F43 -> 11194 | H43: =G43 -> 11194 | I43: =H43 -> 11194 | J43: =I43 -> 11194 | K43: =J43 -> 11194
B44: Unearned & Deferred Revenue | D44: 3640 | E44: 4028 | F44: 4487 | G44: =F44 -> 4487 | H44: =G44 -> 4487 | I44: =H44 -> 4487 | J44: =I44 -> 4487 | K44: =J44 -> 4487
B45: Income Tax Liabilities | D45: 11433 | E45: 12715 | F45: 14751 | G45: =Assumptions!G67 -> 16013.04 | H45: =Assumptions!H67 -> 17943.436 | I45: =Assumptions!I67 -> 20185.412 | J45: =Assumptions!J67 -> 22681.09 | K45: =Assumptions!K67 -> 25454.891
B46: Other Current Liabilities | D46: 11183 | E46: 12253 | F46: 13844 | G46: =F46 -> 13844 | H46: =G46 -> 13844 | I46: =H46 -> 13844 | J46: =I46 -> 13844 | K46: =J46 -> 13844
B47: Total Current liabilities | D47: =SUM(D41:D46) -> 46104 | E47: =SUM(E41:E46) -> 53001 | F47: =SUM(F41:F46) -> 60914 | G47: =SUM(G41:G46) -> 61944.185 | H47: =SUM(H41:H46) -> 65219.952 | I47: =SUM(I41:I46) -> 69017.147 | J47: =SUM(J41:J46) -> 73219.957 | K47: =SUM(K41:K46) -> 77867.644
B49: Total Equity and Liabilities | D49: =SUM(D33,D38,D47) -> 146449 | E49: =SUM(E33,E38,E47) -> 159629 | F49: =SUM(F33,F38,F47) -> 182372 | G49: =SUM(G33,G38,G47) -> 194018.32 | H49: =SUM(H33,H38,H47) -> 205224.7 | I49: =SUM(I33,I38,I47) -> 217943.41 | J49: =SUM(J33,J38,J47) -> 228829.26 | K49: =SUM(K33,K38,K47) -> 240977.29
...

Sheet Cash Flow
B1: TCS — Consolidated Statement of Cash Flows
B2: ₹ Crore | Source: Annual Reports FY25, FY26
B3: Year | D3: 45382 | E3: 45747 | F3: 46112 | G3: 46477 | H3: 46843 | I3: 47208 | J3: 47573 | K3: 47938
B4: Cashflow from Operating Activities
B5: PAT | G5: ='P&L'!G32 -> 58978.502 | H5: ='P&L'!H32 -> 66088.448 | I5: ='P&L'!I32 -> 74345.994 | J5: ='P&L'!J32 -> 83537.963 | K5: ='P&L'!K32 -> 93754.298
B6: Add: Depreciation | G6: =Assumptions!G29 -> 4640.601 | H6: =Assumptions!H29 -> 4537.4384 | I6: =Assumptions!I29 -> 4428.9418 | J6: =Assumptions!J29 -> 4308.7484 | K6: =Assumptions!K29 -> 4194.0956
B7: Add: Interest Expense | G7: =-'P&L'!G22 -> 1227 | H7: =-'P&L'!H22 -> 1227 | I7: =-'P&L'!I22 -> 1227 | J7: =-'P&L'!J22 -> 1227 | K7: =-'P&L'!K22 -> 1227
B8: Add : Tax expense | F8: {='Balance Sheet'!F+F8} -> 0 | G8: ='P&L'!G30 -> 19948.074 | H8: ='P&L'!H30 -> 22352.844 | I8: ='P&L'!I30 -> 25145.763 | J8: ='P&L'!J30 -> 28254.727 | K8: ='P&L'!K30 -> 31710.159
B9: Less : Other Income | G9: =-'P&L'!G21 -> -4871.9801 | H9: =-'P&L'!H21 -> -5321.6615 | I9: =-'P&L'!I21 -> -5841.483 | J9: =-'P&L'!J21 -> -6412.0809 | K9: =-'P&L'!K21 -> -7038.4149
B10: Net Change in Working Capital (excluding cash and overdraft)
B11: Add : Trade Payable | G11: ='Balance Sheet'!G42-'Balance Sheet'!F42 -> -231.8554 | H11: ='Balance Sheet'!H42-'Balance Sheet'!G42 -> 1345.3712 | I11: ='Balance Sheet'!I42-'Balance Sheet'!H42 -> 1555.2186 | J11: ='Balance Sheet'!J42-'Balance Sheet'!I42 -> 1707.1328 | K11: ='Balance Sheet'!K42-'Balance Sheet'!J42 -> 1873.886
B12: Unearned or Deferred Revenue | G12: ='Balance Sheet'!G44-'Balance Sheet'!F44 -> 0 | H12: ='Balance Sheet'!H44-'Balance Sheet'!G44 -> 0 | I12: ='Balance Sheet'!I44-'Balance Sheet'!H44 -> 0 | J12: ='Balance Sheet'!J44-'Balance Sheet'!I44 -> 0 | K12: ='Balance Sheet'!K44-'Balance Sheet'!J44 -> 0
B13: Trade Receivable | G13: ='Balance Sheet'!F19-'Balance Sheet'!G19 -> -708.68109 | H13: ='Balance Sheet'!G19-'Balance Sheet'!H19 -> -6315.3807 | I13: ='Balance Sheet'!H19-'Balance Sheet'!I19 -> -7300.4368 | J13: ='Balance Sheet'!I19-'Balance Sheet'!J19 -> -8013.5458 | K13: ='Balance Sheet'!J19-'Balance Sheet'!K19 -> -8796.3114
B14: Inventories | G14: ='Balance Sheet'!F17-'Balance Sheet'!G17 -> 0 | H14: ='Balance Sheet'!G17-'Balance Sheet'!H17 -> 0 | I14: ='Balance Sheet'!H17-'Balance Sheet'!I17 -> 0 | J14: ='Balance Sheet'!I17-'Balance Sheet'!J17 -> 0 | K14: ='Balance Sheet'!J17-'Balance Sheet'!K17 -> 0
B15: Other Current Asset | G15: ='Balance Sheet'!F22-'Balance Sheet'!G22 -> 0 | H15: ='Balance Sheet'!G22-'Balance Sheet'!H22 -> 0 | I15: ='Balance Sheet'!H22-'Balance Sheet'!I22 -> 0 | J15: ='Balance Sheet'!I22-'Balance Sheet'!J22 -> 0 | K15: ='Balance Sheet'!J22-'Balance Sheet'!K22 -> 0
B16: Net Change in Working Capital | G16: =SUM(G11:G15) -> -940.53649 | H16: =SUM(H11:H15) -> -4970.0096 | I16: =SUM(I11:I15) -> -5745.2183 | J16: =SUM(J11:J15) -> -6306.413 | K16: =SUM(K11:K15) -> -6922.4253
B17: Tax Paid | G17: =-G50 -> -18686.034 | H17: =-H50 -> -20422.449 | I17: =-I50 -> -22903.786 | J17: =-J50 -> -25759.049 | K17: =-K50 -> -28936.359
B20: Cashflow from Operations | G20: =SUM(G5:G9,G16,G17) -> 60295.627 | H20: =SUM(H5:H9,H16,H17) -> 63491.611 | I20: =SUM(I5:I9,I16,I17) -> 70657.212 | J20: =SUM(J5:J9,J16,J17) -> 78850.895 | K20: =SUM(K5:K9,K16,K17) -> 87988.354
B22: Bank | G22: ='Balance Sheet'!F21-'Balance Sheet'!G21 -> -273.753 | H22: ='Balance Sheet'!G21-'Balance Sheet'!H21 -> -624.38347 | I22: ='Balance Sheet'!H21-'Balance Sheet'!I21 -> -721.77312 | J22: ='Balance Sheet'!I21-'Balance Sheet'!J21 -> -792.27614 | K22: ='Balance Sheet'!J21-'Balance Sheet'!K21 -> -869.66592
B23: Less: Investments | G23: ='Balance Sheet'!F18-'Balance Sheet'!G18 -> -2736.1449 | H23: ='Balance Sheet'!G18-'Balance Sheet'!H18 -> -3369.4997 | I23: ='Balance Sheet'!H18-'Balance Sheet'!I18 -> -3895.0652 | J23: ='Balance Sheet'!I18-'Balance Sheet'!J18 -> -4275.5364 | K23: ='Balance Sheet'!J18-'Balance Sheet'!K18 -> -4693.1721
B24: Less: Capex | G24: =-'Asset schedule'!G6 -> -2806.8791 | H24: =-'Asset schedule'!H6 -> -3037.277 | I24: =-'Asset schedule'!I6 -> -3301.7731 | J24: =-'Asset schedule'!J6 -> -3605.8112 | K24: =-'Asset schedule'!K6 -> -3955.8753
B25: Add: Disposal of Assets | G25: =-'Asset schedule'!G7 -> 935.55569 | H25: =-'Asset schedule'!H7 -> 980.20799 | I25: =-'Asset schedule'!I7 -> 1029.2924 | J25: =-'Asset schedule'!J7 -> 1083.5169 | K25: =-'Asset schedule'!K7 -> 1143.7022
B26: Less: Increase in Capital WIP | G26: ='Balance Sheet'!F7-'Balance Sheet'!G7 -> 501.82901 | H26: ='Balance Sheet'!G7-'Balance Sheet'!H7 -> -103.24404 | I26: ='Balance Sheet'!H7-'Balance Sheet'!I7 -> -113.49194 | J26: ='Balance Sheet'!I7-'Balance Sheet'!J7 -> -125.37656 | K26: ='Balance Sheet'!J7-'Balance Sheet'!K7 -> -139.1592
B27: Cashflow from Investment Activities | G27: =SUM(G22:G26) -> -4379.3923 | H27: =SUM(H22:H26) -> -6154.1962 | I27: =SUM(I22:I26) -> -7002.8109 | J27: =SUM(J22:J26) -> -7715.4834 | K27: =SUM(K22:K26) -> -8514.1703
B28: Intangible Assets | G28: -200 | H28: -200 | I28: -200 | J28: -200 | K28: -200
B29: ROU Addition | G29: =-'Asset schedule'!G22 -> -1866 | H29: =-'Asset schedule'!H22 -> -1866 | I29: =-'Asset schedule'!I22 -> -1866 | J29: =-'Asset schedule'!J22 -> -1866 | K29: =-'Asset schedule'!K22 -> -1866
B30: Other Income | G30: ='P&L'!G21 -> 4871.9801 | H30: ='P&L'!H21 -> 5321.6615 | I30: ='P&L'!I21 -> 5841.483 | J30: ='P&L'!J21 -> 6412.0809 | K30: ='P&L'!K21 -> 7038.4149
B31: Dividends Paid | G31: ='Equity Schedule'!G7 -> -48362.372 | H31: ='Equity Schedule'!H7 -> -58157.834 | I31: ='Equity Schedule'!I7 -> -65424.475 | J31: ='Equity Schedule'!J7 -> -76854.926 | K31: ='Equity Schedule'!K7 -> -86253.954
B32: Interest Expense | G32: ='P&L'!G22 -> -1227 | H32: ='P&L'!H22 -> -1227 | I32: ='P&L'!I22 -> -1227 | J32: ='P&L'!J22 -> -1227 | K32: ='P&L'!K22 -> -1227
B33: Cashflow from Financing Activities | G33: =SUM(G28:G32) -> -46783.392 | H33: =SUM(H28:H32) -> -56129.173 | I33: =SUM(I28:I32) -> -62875.992 | J33: =SUM(J28:J32) -> -73735.845 | K33: =SUM(K28:K32) -> -82508.54
B36: Net Cash Flow | G36: =SUM(G20,G27,G33) -> 9132.8426 | H36: =SUM(H20,H27,H33) -> 1208.2421 | I36: =SUM(I20,I27,I33) -> 778.40849 | J36: =SUM(J20,J27,J33) -> -2600.433 | K36: =SUM(K20,K27,K33) -> -3034.3558
B38: Cash Balance
B39: Opening Balance | G39: =F41 -> 6417 | H39: =G41 -> 15549.843 | I39: =H41 -> 16758.085 | J39: =I41 -> 17536.493 | K39: =J41 -> 14936.06
B40: Net Cashflow | G40: =G36 -> 9132.8426 | H40: =H36 -> 1208.2421 | I40: =I36 -> 778.40849 | J40: =J36 -> -2600.433 | K40: =K36 -> -3034.3558
B41: Closing Balance | F41: 6417 | G41: =SUM(G39:G40) -> 15549.843 | H41: =SUM(H39:H40) -> 16758.085 | I41: =SUM(I39:I40) -> 17536.493 | J41: =SUM(J39:J40) -> 14936.06 | K41: =SUM(K39:K40) -> 11901.704
B46: Tax Paid
B47: Opening Tax Liability | G47: ='Balance Sheet'!F45 -> 14751 | H47: ='Balance Sheet'!G45 -> 16013.04 | I47: ='Balance Sheet'!H45 -> 17943.436 | J47: ='Balance Sheet'!I45 -> 20185.412 | K47: ='Balance Sheet'!J45 -> 22681.09
B48: Tax Expense | G48: ='P&L'!G30 -> 19948.074 | H48: ='P&L'!H30 -> 22352.844 | I48: ='P&L'!I30 -> 25145.763 | J48: ='P&L'!J30 -> 28254.727 | K48: ='P&L'!K30 -> 31710.159
B49: Closing Tax liability | G49: =-'Balance Sheet'!G45 -> -16013.04 | H49: =-'Balance Sheet'!H45 -> -17943.436 | I49: =-'Balance Sheet'!I45 -> -20185.412 | J49: =-'Balance Sheet'!J45 -> -22681.09 | K49: =-'Balance Sheet'!K45 -> -25454.891
B50: Tax Paid | G50: =SUM(G47:G49) -> 18686.034 | H50: =SUM(H47:H49) -> 20422.449 | I50: =SUM(I47:I49) -> 22903.786 | J50: =SUM(J47:J49) -> 25759.049 | K50: =SUM(K47:K49) -> 28936.359

Sheet Asset schedule
B1: TCS
B2: ₹ Crore | Source: Annual Reports FY25, FY26
B3: Year | C3: 45016 | D3: 45382 | E3: 45747 | F3: 46112 | G3: 46477 | H3: 46843 | I3: 47208 | J3: 47573 | K3: 47938
B4: PPE Schedule
B5: Opening Gross Block | C5: 30300 | D5: =C9 -> 32344 | E5: =D9 -> 33853 | F5: =E9 -> 37277 | G5: =F9 -> 39208 | H5: =G9 -> 41079.323 | I5: =H9 -> 43136.392 | J5: =I9 -> 45408.873 | K5: =J9 -> 47931.167
B6: Add: CAPEX | C6: 2314 | D6: 1923 | E6: 4306 | F6: 2608 | G6: =Assumptions!G40 -> 2806.8791 | H6: =Assumptions!H40 -> 3037.277 | I6: =Assumptions!I40 -> 3301.7731 | J6: =Assumptions!J40 -> 3605.8112 | K6: =Assumptions!K40 -> 3955.8753
B7: Less Asset dispose or sold | C7: -458 | D7: -502 | E7: -869 | F7: -1459 | G7: =-(G5*Assumptions!G39) -> -935.55569 | H7: =-(H5*Assumptions!H39) -> -980.20799 | I7: =-(I5*Assumptions!I39) -> -1029.2924 | J7: =-(J5*Assumptions!J39) -> -1083.5169 | K7: =-(K5*Assumptions!K39) -> -1143.7022
B8: Add/Less : Translation Difference | C8: 188 | D8: 88 | E8: -13 | F8: 782
B9: Closing Gross Block | C9: =SUM(C5:C8) -> 32344 | D9: =SUM(D5:D8) -> 33853 | E9: =SUM(E5:E8) -> 37277 | F9: =SUM(F5:F8) -> 39208 | G9: =SUM(G5:G8) -> 41079.323 | H9: =SUM(H5:H8) -> 43136.392 | I9: =SUM(I5:I8) -> 45408.873 | J9: =SUM(J5:J8) -> 47931.167 | K9: =SUM(K5:K8) -> 50743.34
B10: Less : Accumalated Depreciation | C10: -22114 | D10: -24477 | E10: -26299 | F10: -28176 | G10: =-G16 -> -30840.601 | H10: =-H16 -> -33425.039 | I10: =-I16 -> -35920.981 | J10: =-J16 -> -38318.73 | K10: =-K16 -> -40606.825
B11: Net Block | C11: =SUM(C9:C10) -> 10230 | D11: =SUM(D9:D10) -> 9376 | E11: =SUM(E9:E10) -> 10978 | F11: =SUM(F9:F10) -> 11032 | G11: =SUM(G9:G10) -> 10238.722 | H11: =SUM(H9:H10) -> 9711.353 | I11: =SUM(I9:I10) -> 9487.8918 | J11: =SUM(J9:J10) -> 9612.4378 | K11: =SUM(K9:K10) -> 10136.515
B13: Accumalated Depreciation For PPE
B14: Opening balance | G14: =F16 -> 28176 | H14: =G16 -> 30840.601 | I14: =H16 -> 33425.039 | J14: =I16 -> 35920.981 | K14: =J16 -> 38318.73
B15: Depreciation for current year | G15: =(AVERAGE(F9:G9))*Assumptions!G36 -> 2664.601 | H15: =(AVERAGE(G9:H9))*Assumptions!H36 -> 2584.4384 | I15: =(AVERAGE(H9:I9))*Assumptions!I36 -> 2495.9418 | J15: =(AVERAGE(I9:J9))*Assumptions!J36 -> 2397.7484 | K15: =(AVERAGE(J9:K9))*Assumptions!K36 -> 2288.0956
B16: Closing Balance | C16: 22114 | D16: 24477 | E16: 26299 | F16: 28176 | G16: =SUM(G14:G15) -> 30840.601 | H16: =SUM(H14:H15) -> 33425.039 | I16: =SUM(I14:I15) -> 35920.981 | J16: =SUM(J14:J15) -> 38318.73 | K16: =SUM(K14:K15) -> 40606.825
B19: ROU Asset
B20: ROU
B21: Opening balance | G21: =F24 -> 11027 | H21: =G24 -> 11027 | I21: =H24 -> 11027 | J21: =I24 -> 11027 | K21: =J24 -> 11027
B22: Addition | G22: =G23 -> 1866 | H22: =H23 -> 1866 | I22: =I23 -> 1866 | J22: =J23 -> 1866 | K22: =K23 -> 1866
B23: Depreciation on ROU | C23: 1634 | D23: 1716 | E23: 1820 | F23: 1866 | G23: =F23 -> 1866 | H23: =G23 -> 1866 | I23: =H23 -> 1866 | J23: =I23 -> 1866 | K23: =J23 -> 1866
B24: Closing balance | F24: 11027 | G24: =G21+G22-G23 -> 11027 | H24: =H21+H22-H23 -> 11027 | I24: =I21+I22-I23 -> 11027 | J24: =J21+J22-J23 -> 11027 | K24: =K21+K22-K23 -> 11027
B29: Other Intangible Assets
B31: Opening (Net) | G31: =F34 -> 176 | H31: =G43 -> 266 | I31: =H43 -> 379 | J31: =I43 -> 512 | K31: =J43 -> 667
B32: Organic Addition (Assumed 200 cr) | G32: 200 | H32: 200 | I32: 200 | J32: 200 | K32: 200
B34: Closing (Net) | F34: 176 | G34: =SUM(G31:G33) -> 376 | H34: =SUM(H31:H33) -> 466 | I34: =SUM(I31:I33) -> 579 | J34: =SUM(J31:J33) -> 712 | K34: =SUM(K31:K33) -> 867
B37: Existing intangibles Amort. | G37: 70 | H37: 47 | I37: 27 | J37: 5 | K37: -
B38: Additional Amort. | G38: 40 | H38: 40 | I38: 40 | J38: 40 | K38: 40
B39: Total | G39: =SUM(G37:G38) -> 110 | H39: =SUM(H37:H38) -> 87 | I39: =SUM(I37:I38) -> 67 | J39: =SUM(J37:J38) -> 45 | K39: =SUM(K37:K38) -> 40
B43: Final Net Intangible Assets | G43: =G34-G39 -> 266 | H43: =H34-H39 -> 379 | I43: =I34-I39 -> 512 | J43: =J34-J39 -> 667 | K43: =K34-K39 -> 827

Sheet Equity Schedule
B1: TCS
B2: ₹ Crore | Source: Annual Reports FY25, FY26
B3: Year | C3: 45016 | D3: 45382 | E3: 45747 | F3: 46112 | G3: 46477 | H3: 46843 | I3: 47208 | J3: 47573 | K3: 47938
B5: Opening Equity | G5: =F8 -> 106878 | H5: =G8 -> 117494.13 | I5: =H8 -> 125424.74 | J5: =I8 -> 134346.26 | K5: =J8 -> 141029.3
B6: Net Profit | G6: ='P&L'!G32 -> 58978.502 | H6: ='P&L'!H32 -> 66088.448 | I6: ='P&L'!I32 -> 74345.994 | J6: ='P&L'!J32 -> 83537.963 | K6: ='P&L'!K32 -> 93754.298
B7: Dividend | G7: =-G6*Assumptions!G65 -> -48362.372 | H7: =-H6*Assumptions!H65 -> -58157.834 | I7: =-I6*Assumptions!I65 -> -65424.475 | J7: =-J6*Assumptions!J65 -> -76854.926 | K7: =-K6*Assumptions!K65 -> -86253.954
B8: Closing Equity | F8: ='Balance Sheet'!F30 -> 106878 | G8: =SUM(G5:G7) -> 117494.13 | H8: =SUM(H5:H7) -> 125424.74 | I8: =SUM(I5:I7) -> 134346.26 | J8: =SUM(J5:J7) -> 141029.3 | K8: =SUM(K5:K7) -> 148529.64

Sheet Valuation
B1: TCS - DCF Valuation
B2: Year | D2: 45382 | E2: 45747 | F2: 46112 | G2: 46477 | H2: 46843 | I2: 47208 | J2: 47573 | K2: 47938
B3: PAT | G3: ='P&L'!G32 -> 58978.502 | H3: ='P&L'!H32 -> 66088.448 | I3: ='P&L'!I32 -> 74345.994 | J3: ='P&L'!J32 -> 83537.963 | K3: ='P&L'!K32 -> 93754.298
B4: D&A | G4: =Assumptions!G29 -> 4640.601 | H4: =Assumptions!H29 -> 4537.4384 | I4: =Assumptions!I29 -> 4428.9418 | J4: =Assumptions!J29 -> 4308.7484 | K4: =Assumptions!K29 -> 4194.0956
B5: Capex | G5: =-'Asset schedule'!G6 -> -2806.8791 | H5: =-'Asset schedule'!H6 -> -3037.277 | I5: =-'Asset schedule'!I6 -> -3301.7731 | J5: =-'Asset schedule'!J6 -> -3605.8112 | K5: =-'Asset schedule'!K6 -> -3955.8753
B6: Change in WIP | G6: ='Cash Flow'!G26 -> 501.82901 | H6: ='Cash Flow'!H26 -> -103.24404 | I6: ='Cash Flow'!I26 -> -113.49194 | J6: ='Cash Flow'!J26 -> -125.37656 | K6: ='Cash Flow'!K26 -> -139.1592
B7: Change in Working Capital | G7: ='Cash Flow'!G16 -> -940.53649 | H7: ='Cash Flow'!H16 -> -4970.0096 | I7: ='Cash Flow'!I16 -> -5745.2183 | J7: ='Cash Flow'!J16 -> -6306.413 | K7: ='Cash Flow'!K16 -> -6922.4253
B8: Net Borrowings | G8: 0 | H8: 0 | I8: 0 | J8: 0 | K8: 0
B9: FFCE | G9: =SUM(G3:G7) -> 60373.517 | H9: =SUM(H3:H7) -> 62515.356 | I9: =SUM(I3:I7) -> 69614.453 | J9: =SUM(J3:J7) -> 77809.11 | K9: =SUM(K3:K7) -> 86930.934
B12: Risk-Free Rate | C12: 0.063
B13: Beta | C13: 0.9
B14: Market Risk Premium | C14: 0.06
B15: Cost of Equity | C15: =C12+(C13*C14) -> 0.117 | D15: Col input
B17: Terminal Growth Rate | C17: 0.045
B18: Terminal Value | C18: =K9*(1+C17)/(C15-C17) -> 1261705.9
B20: Cash Flows | G20: =G9 -> 60373.517 | H20: =H9 -> 62515.356 | I20: =I9 -> 69614.453 | J20: =J9 -> 77809.11 | K20: =K9 -> 86930.934 | L20: =C18 -> 1261705.9
B22: Entreprise value/Equity Valu (FCFE discounted) | C22: =NPV(C15,G20:L20) -> 903670.18
B23: No. of Shares (in Crores) | C23: 362
B24: Share Price | C24: =C22/C23 -> 2496.3265
E26: Terminal value
D27: =C24 -> 2496.3265 | E27: =F27-0.5% -> 0.035 | F27: =G27-0.5% -> 0.04 | G27: 0.045 | H27: =G27+0.5% -> 0.05 | I27: =H27+0.5% -> 0.055
C28: Cost of Equity | D28: =D29-0.5% -> 0.107 | E28: 2596.7283 | F28: 2746.452 | G28: 2920.3246 | H28: 3124.7012 | I28: 3368.3809
D29: =D30-0.5% -> 0.112 | E29: 2418.5104 | F29: 2545.8867 | G29: 2692.2743 | H29: 2862.2729 | I29: 3062.0959
D30: 0.117 | E30: 2262.4139 | F30: 2371.7756 | G30: 2496.3265 | H30: 2639.467 | I30: 2805.6947
D31: =D30+0.5% -> 0.122 | E31: 2124.6087 | F31: 2219.2626 | G31: 2326.2092 | H31: 2448.0094 | I31: 2587.9889
D32: =D31+0.5% -> 0.127 | E32: 2002.098 | F32: 2084.6085 | G32: 2177.1812 | H32: 2281.7764 | I32: 2400.8987
